Workbook

Sheet Cover
A1: INTEGRATED FINANCIAL MODEL
A2: The Coca-Cola Company (NYSE: KO)
A4: 3-Statement Forecast & DCF Valuation
A6: Historical Period: 2022–2025 | D6: Forecast Period: 2026–2030
A8: Prepared by: Paridhi Jain

Sheet Assumptions
A1: KEY ASSUMPTIONS
A3: Fiscal Year | B3: 2022 | C3: 2023 | D3: 2024 | E3: 2025 | F3: 2026E | G3: 2027E | H3: 2028E | I3: 2029E | J3: 2030E
A5: Revenue Growth | B5: ='Income Statement'!B5 -> — | C5: ='Income Statement'!C5 -> 0.06394754 | D5: ='Income Statement'!D5 -> 0.028565808 | E5: ='Income Statement'!E5 -> 0.018699135 | F5: 0.05 | G5: 0.045 | H5: 0.04 | I5: 0.035 | J5: 0.03
A6: COGS % of Revenue | B6: ='Income Statement'!B6/'Income Statement'!B4 -> 0.41856571 | C6: ='Income Statement'!C6/'Income Statement'!C4 -> 0.40477335 | D6: ='Income Statement'!D6/'Income Statement'!D4 -> 0.38936699 | E6: ='Income Statement'!E6/'Income Statement'!E4 -> 0.38374252 | F6: 0.38 | G6: 0.38 | H6: 0.38 | I6: 0.38 | J6: 0.38
A7: SG&A % of Revenue | B7: ='Income Statement'!B9/'Income Statement'!B4 -> 0.29950702 | C7: ='Income Statement'!C9/'Income Statement'!C4 -> 0.30537221 | D7: ='Income Statement'!D9/'Income Statement'!D4 -> 0.30985317 | E7: ='Income Statement'!E9/'Income Statement'!E4 -> 0.30289314 | F7: 0.3 | G7: 0.3 | H7: 0.3 | I7: 0.3 | J7: 0.3
A8: Other Operating Charges % of Revenue | B8: ='Income Statement'!B10/'Income Statement'!B4 -> 0.028253186 | C8: ='Income Statement'!C10/'Income Statement'!C4 -> 0.042641081 | D8: ='Income Statement'!D10/'Income Statement'!D4 -> 0.088459659 | E8: ='Income Statement'!E10/'Income Statement'!E4 -> 0.026303164 | F8: 0.03 | G8: 0.03 | H8: 0.03 | I8: 0.03 | J8: 0.03
A9: Tax Rate | B9: ='Income Statement'!B18/'Income Statement'!B17 -> 0.1809858 | C9: ='Income Statement'!C18/'Income Statement'!C17 -> 0.17364114 | D9: ='Income Statement'!D18/'Income Statement'!D17 -> 0.18622956 | E9: ='Income Statement'!E18/'Income Statement'!E17 -> 0.17883485 | F9: 0.199 | G9: 0.2 | H9: 0.2 | I9: 0.2 | J9: 0.2
A10: D&A % of Revenue | B10: =Historicals!B57/Historicals!B7 -> 0.0292996 | C10: =Historicals!C57/Historicals!C7 -> 0.024653582 | D10: =Historicals!D57/Historicals!D7 -> 0.022842694 | E10: =Historicals!E57/Historicals!E7 -> 0.021901921 | F10: 0.022 | G10: 0.022 | H10: 0.022 | I10: 0.022 | J10: 0.022
A11: CapEx % of Revenue | B11: =-Historicals!B72/Historicals!B7 -> 0.034508418 | C11: =-Historicals!C72/Historicals!C7 -> 0.040477335 | D11: =-Historicals!D72/Historicals!D7 -> 0.043857972 | E11: =-Historicals!E72/Historicals!E7 -> 0.04405415 | F11: 0.044 | G11: 0.044 | H11: 0.044 | I11: 0.044 | J11: 0.044
A12: Dividend Payout Ratio | B12: =-Historicals!B82/'Income Statement'!B20 -> 0.79573712 | C12: =-Historicals!C82/'Income Statement'!C20 -> 0.74296926 | D12: =-Historicals!D82/'Income Statement'!D20 -> 0.78495633 | E12: =-Historicals!E82/'Income Statement'!E20 -> 0.66826521 | F12: 0.67 | G12: 0.67 | H12: 0.67 | I12: 0.67 | J12: 0.67

Sheet Historicals
A1: HISTORICAL FINANCIALS
A3: $ in millions
B4: 2022A | C4: 2023A | D4: 2024A | E4: 2025A
A6: INCOME STATEMENT
A7: Net Operating Revenues | B7: 43004 | C7: 45754 | D7: 47061 | E7: 47941
A8: Cost of Goods Sold | B8: 18000 | C8: 18520 | D8: 18324 | E8: 18397
A9: Gross Profit | B9: 25004 | C9: 27234 | D9: 28737 | E9: 29544
A10: SG&A | B10: 12880 | C10: 13972 | D10: 14582 | E10: 14521
A11: Other Operating Charges | B11: 1215 | C11: 1951 | D11: 4163 | E11: 1261
A12: Operating Income | B12: 10909 | C12: 11311 | D12: 9992 | E12: 13762
A13: Interest Income | B13: 449 | C13: 907 | D13: 988 | E13: 786
A14: Interest Expense | B14: 882 | C14: 1527 | D14: 1656 | E14: 1654
A15: Equity Income (Loss) - Net | B15: 1472 | C15: 1691 | D15: 1770 | E15: 2031
A16: Other Income (Loss) - Net | B16: -262 | C16: 570 | D16: 1992 | E16: 1073
A17: Income Before Income Taxes | B17: 11686 | C17: 12952 | D17: 13086 | E17: 15998
A18: Income Taxes | B18: 2115 | C18: 2249 | D18: 2437 | E18: 2861
A19: Consolidated Net Income | B19: 9571 | C19: 10703 | D19: 10649 | E19: 13137
A22: BALANCE SHEET
A23: Cash & Cash Equivalents | B23: 9519 | C23: 9366 | D23: 10828 | E23: 10270
A24: Short-Term Investments | B24: 1043 | C24: 2997 | D24: 2020 | E24: 3602
A25: Marketable Securities | B25: 1069 | C25: 1300 | D25: 1723 | E25: 1934
A26: Accounts Receivable | B26: 3487 | C26: 3410 | D26: 3569 | E26: 3038
A27: Inventories | B27: 4233 | C27: 4424 | D27: 4728 | E27: 4425
A28: Prepaid Expenses & Other Current Assets | B28: 3240 | C28: 5235 | D28: 2998 | E28: 2433
A29: Assets Held for Sale | B29: — | C29: — | D29: 131 | E29: 5342
A30: Total Current Assets | B30: 22591 | C30: 26732 | D30: 25997 | E30: 31044
A31: Equity Method Investments | B31: 18264 | C31: 19671 | D31: 18087 | E31: 20235
A32: Deferred Income Tax Assets | B32: 1746 | C32: 1561 | D32: 1319 | E32: 1206
A33: PP&E, Net | B33: 9841 | C33: 9236 | D33: 10303 | E33: 9613
A34: Trademarks with Indefinite Lives | B34: 14214 | C34: 14349 | D34: 13301 | E34: 12531
A35: Goodwill | B35: 18782 | C35: 18358 | D35: 18139 | E35: 15491
A36: Other Noncurrent Assets | B36: 7325 | C36: 7796 | D36: 13403 | E36: 14696
A37: Total Assets | B37: 92763 | C37: 97703 | D37: 100549 | E37: 104816
A38: Accounts Payable & Accrued Expenses | B38: 15749 | C38: 15485 | D38: 21712 | E38: 14813
A39: Loans & Notes Payable | B39: 2373 | C39: 4557 | D39: 1499 | E39: 1551
A40: Current Maturities of Long-Term Debt | B40: 399 | C40: 1960 | D40: 648 | E40: 1822
A41: Accrued Income Taxes | B41: 1203 | C41: 1569 | D41: 1387 | E41: 525
A42: Liabilities Held for Sale | B42: — | C42: — | D42: 3 | E42: 2570
A43: Total Current Liabilities | B43: 19724 | C43: 23571 | D43: 25249 | E43: 21281
A44: Long-Term Debt | B44: 36377 | C44: 35547 | D44: 42375 | E44: 42119
...

Sheet Income Statement
A1: INCOME STATEMENT
B3: 2022A | C3: 2023A | D3: 2024A | E3: 2025A | F3: 2026E | G3: 2027E | H3: 2028E | I3: 2029E | J3: 2030E
A4: Revenue | B4: =Historicals!B7 -> 43004 | C4: =Historicals!C7 -> 45754 | D4: =Historicals!D7 -> 47061 | E4: =Historicals!E7 -> 47941 | F4: =E4*(1+Assumptions!F5) -> 50338.05 | G4: =F4*(1+Assumptions!G5) -> 52603.262 | H4: =G4*(1+Assumptions!H5) -> 54707.393 | I4: =H4*(1+Assumptions!I5) -> 56622.151 | J4: =I4*(1+Assumptions!J5) -> 58320.816
A5: Revenue Growth | B5: — | C5: =C4/B4-1 -> 0.06394754 | D5: =D4/C4-1 -> 0.028565808 | E5: =E4/D4-1 -> 0.018699135 | F5: =Assumptions!F5 -> 0.05 | G5: =Assumptions!G5 -> 0.045 | H5: =Assumptions!H5 -> 0.04 | I5: =Assumptions!I5 -> 0.035 | J5: =Assumptions!J5 -> 0.03
A6: COGS | B6: =Historicals!B8 -> 18000 | C6: =Historicals!C8 -> 18520 | D6: =Historicals!D8 -> 18324 | E6: =Historicals!E8 -> 18397 | F6: =F4*Assumptions!F6 -> 19128.459 | G6: =G4*Assumptions!G6 -> 19989.24 | H6: =H4*Assumptions!H6 -> 20788.809 | I6: =I4*Assumptions!I6 -> 21516.418 | J6: =J4*Assumptions!J6 -> 22161.91
A7: Gross Profit | B7: =Historicals!B9 -> 25004 | C7: =Historicals!C9 -> 27234 | D7: =Historicals!D9 -> 28737 | E7: =Historicals!E9 -> 29544 | F7: =F4-F6 -> 31209.591 | G7: =G4-G6 -> 32614.023 | H7: =H4-H6 -> 33918.584 | I7: =I4-I6 -> 35105.734 | J7: =J4-J6 -> 36158.906
A8: Gross Margin | B8: =B7/B4 -> 0.58143429 | C8: =C7/C4 -> 0.59522665 | D8: =D7/D4 -> 0.61063301 | E8: =E7/E4 -> 0.61625748 | F8: =F7/F4 -> 0.62 | G8: =G7/G4 -> 0.62 | H8: =H7/H4 -> 0.62 | I8: =I7/I4 -> 0.62 | J8: =J7/J4 -> 0.62
A9: SG&A | B9: =Historicals!B10 -> 12880 | C9: =Historicals!C10 -> 13972 | D9: =Historicals!D10 -> 14582 | E9: =Historicals!E10 -> 14521 | F9: =F4*Assumptions!F7 -> 15101.415 | G9: =G4*Assumptions!G7 -> 15780.979 | H9: =H4*Assumptions!H7 -> 16412.218 | I9: =I4*Assumptions!I7 -> 16986.645 | J9: =J4*Assumptions!J7 -> 17496.245
A10: Other Operating Charges | B10: =Historicals!B11 -> 1215 | C10: =Historicals!C11 -> 1951 | D10: =Historicals!D11 -> 4163 | E10: =Historicals!E11 -> 1261 | F10: =F4*Assumptions!F8 -> 1510.1415 | G10: =G4*Assumptions!G8 -> 1578.0979 | H10: =H4*Assumptions!H8 -> 1641.2218 | I10: =I4*Assumptions!I8 -> 1698.6645 | J10: =J4*Assumptions!J8 -> 1749.6245
A11: Operating Income | B11: =Historicals!B12 -> 10909 | C11: =Historicals!C12 -> 11311 | D11: =Historicals!D12 -> 9992 | E11: =Historicals!E12 -> 13762 | F11: =F7-F9-F10 -> 14598.034 | G11: =G7-G9-G10 -> 15254.946 | H11: =H7-H9-H10 -> 15865.144 | I11: =I7-I9-I10 -> 16420.424 | J11: =J7-J9-J10 -> 16913.037
A12: Operating Margin | B12: =B11/B4 -> 0.25367408 | C12: =C11/C4 -> 0.24721336 | D12: =D11/D4 -> 0.21232018 | E12: =E11/E4 -> 0.28706118 | F12: =F11/F4 -> 0.29 | G12: =G11/G4 -> 0.29 | H12: =H11/H4 -> 0.29 | I12: =I11/I4 -> 0.29 | J12: =J11/J4 -> 0.29
A13: Interest Income | B13: =Historicals!B13 -> 449 | C13: =Historicals!C13 -> 907 | D13: =Historicals!D13 -> 988 | E13: =Historicals!E13 -> 786 | F13: =$E$13 -> 786 | G13: =$E$13 -> 786 | H13: =$E$13 -> 786 | I13: =$E$13 -> 786 | J13: =$E$13 -> 786
A14: Interest Expense | B14: =Historicals!B14 -> 882 | C14: =Historicals!C14 -> 1527 | D14: =Historicals!D14 -> 1656 | E14: =Historicals!E14 -> 1654 | F14: =Debt!F11 -> 1683.204 | G14: =Debt!G11 -> 1683.204 | H14: =Debt!H11 -> 1683.204 | I14: =Debt!I11 -> 1683.204 | J14: =Debt!J11 -> 1683.204
A15: Equity Income | B15: =Historicals!B15 -> 1472 | C15: =Historicals!C15 -> 1691 | D15: =Historicals!D15 -> 1770 | E15: =Historicals!E15 -> 2031 | F15: =$E$15 -> 2031 | G15: =$E$15 -> 2031 | H15: =$E$15 -> 2031 | I15: =$E$15 -> 2031 | J15: =$E$15 -> 2031
A16: Other Income | B16: =Historicals!B16 -> -262 | C16: =Historicals!C16 -> 570 | D16: =Historicals!D16 -> 1992 | E16: =Historicals!E16 -> 1073 | F16: =$E$16 -> 1073 | G16: =$E$16 -> 1073 | H16: =$E$16 -> 1073 | I16: =$E$16 -> 1073 | J16: =$E$16 -> 1073
A17: Income Before Taxes | B17: =Historicals!B17 -> 11686 | C17: =Historicals!C17 -> 12952 | D17: =Historicals!D17 -> 13086 | E17: =Historicals!E17 -> 15998 | F17: =F11+F13-F14+F15+F16 -> 16804.831 | G17: =G11+G13-G14+G15+G16 -> 17461.742 | H17: =H11+H13-H14+H15+H16 -> 18071.94 | I17: =I11+I13-I14+I15+I16 -> 18627.22 | J17: =J11+J13-J14+J15+J16 -> 19119.833
A18: Income Taxes | B18: =Historicals!B18 -> 2115 | C18: =Historicals!C18 -> 2249 | D18: =Historicals!D18 -> 2437 | E18: =Historicals!E18 -> 2861 | F18: =F17*Assumptions!F9 -> 3344.1613 | G18: =G17*Assumptions!G9 -> 3492.3484 | H18: =H17*Assumptions!H9 -> 3614.388 | I18: =I17*Assumptions!I9 -> 3725.444 | J18: =J17*Assumptions!J9 -> 3823.9665
A19: Tax Rate | B19: =B18/B17 -> 0.1809858 | C19: =C18/C17 -> 0.17364114 | D19: =D18/D17 -> 0.18622956 | E19: =E18/E17 -> 0.17883485 | F19: =F18/F17 -> 0.199 | G19: =G18/G17 -> 0.2 | H19: =H18/H17 -> 0.2 | I19: =I18/I17 -> 0.2 | J19: =J18/J17 -> 0.2
A20: Net Income | B20: =Historicals!B19 -> 9571 | C20: =Historicals!C19 -> 10703 | D20: =Historicals!D19 -> 10649 | E20: =Historicals!E19 -> 13137 | F20: =F17-F18 -> 13460.669 | G20: =G17-G18 -> 13969.394 | H20: =H17-H18 -> 14457.552 | I20: =I17-I18 -> 14901.776 | J20: =J17-J18 -> 15295.866

Sheet Balance Sheet
A1: BALANCE SHEET
B3: 2022A | C3: 2023A | D3: 2024A | E3: 2025A | F3: 2026E | G3: 2027E | H3: 2028E | I3: 2029E | J3: 2030E
A5: ASSETS
A6: Cash & Cash Equivalents | B6: =Historicals!B23 -> 9519 | C6: =Historicals!C23 -> 9366 | D6: =Historicals!D23 -> 10828 | E6: =Historicals!E23 -> 10270 | F6: ='Cash Flow'!F23 -> 13971.407 | G6: ='Cash Flow'!G23 -> 17771.292 | H6: ='Cash Flow'!H23 -> 21661.285 | I6: ='Cash Flow'!I23 -> 25626.716 | J6: ='Cash Flow'!J23 -> 29651.699
A7: Short-Term Investments | B7: =Historicals!B24 -> 1043 | C7: =Historicals!C24 -> 2997 | D7: =Historicals!D24 -> 2020 | E7: =Historicals!E24 -> 3602 | F7: =$E7 -> 3602 | G7: =$E7 -> 3602 | H7: =$E7 -> 3602 | I7: =$E7 -> 3602 | J7: =$E7 -> 3602
A8: Marketable Securities | B8: =Historicals!B25 -> 1069 | C8: =Historicals!C25 -> 1300 | D8: =Historicals!D25 -> 1723 | E8: =Historicals!E25 -> 1934 | F8: =$E8 -> 1934 | G8: =$E8 -> 1934 | H8: =$E8 -> 1934 | I8: =$E8 -> 1934 | J8: =$E8 -> 1934
A9: Accounts Receivable | B9: =Historicals!B26 -> 3487 | C9: =Historicals!C26 -> 3410 | D9: =Historicals!D26 -> 3569 | E9: =Historicals!E26 -> 3038 | F9: ='Working Capital'!F5 -> 3191.4324 | G9: ='Working Capital'!G5 -> 3335.0468 | H9: ='Working Capital'!H5 -> 3468.4487 | I9: ='Working Capital'!I5 -> 3589.8444 | J9: ='Working Capital'!J5 -> 3697.5397
A10: Inventories | B10: =Historicals!B27 -> 4233 | C10: =Historicals!C27 -> 4424 | D10: =Historicals!D27 -> 4728 | E10: =Historicals!E27 -> 4425 | F10: ='Working Capital'!F7 -> 4646.202 | G10: ='Working Capital'!G7 -> 4855.2811 | H10: ='Working Capital'!H7 -> 5049.4924 | I10: ='Working Capital'!I7 -> 5226.2246 | J10: ='Working Capital'!J7 -> 5383.0113
A11: Prepaid Expenses & Other Current Assets | B11: =Historicals!B28 -> 3240 | C11: =Historicals!C28 -> 5235 | D11: =Historicals!D28 -> 2998 | E11: =Historicals!E28 -> 2433 | F11: =$E11 -> 2433 | G11: =$E11 -> 2433 | H11: =$E11 -> 2433 | I11: =$E11 -> 2433 | J11: =$E11 -> 2433
A12: Assets Held for Sale | B12: =Historicals!B29 -> — | C12: =Historicals!C29 -> — | D12: =Historicals!D29 -> 131 | E12: =Historicals!E29 -> 5342 | F12: =$E12 -> 5342 | G12: =$E12 -> 5342 | H12: =$E12 -> 5342 | I12: =$E12 -> 5342 | J12: =$E12 -> 5342
A13: Total Current Assets | B13: =Historicals!B30 -> 22591 | C13: =Historicals!C30 -> 26732 | D13: =Historicals!D30 -> 25997 | E13: =Historicals!E30 -> 31044 | F13: =SUM(F6:F12) -> 35120.041 | G13: =SUM(G6:G12) -> 39272.62 | H13: =SUM(H6:H12) -> 43490.226 | I13: =SUM(I6:I12) -> 47753.785 | J13: =SUM(J6:J12) -> 52043.25
A15: Equity Method Investments | B15: =Historicals!B31 -> 18264 | C15: =Historicals!C31 -> 19671 | D15: =Historicals!D31 -> 18087 | E15: =Historicals!E31 -> 20235 | F15: =$E15 -> 20235 | G15: =$E15 -> 20235 | H15: =$E15 -> 20235 | I15: =$E15 -> 20235 | J15: =$E15 -> 20235
A16: Deferred Income Tax Assets | B16: =Historicals!B32 -> 1746 | C16: =Historicals!C32 -> 1561 | D16: =Historicals!D32 -> 1319 | E16: =Historicals!E32 -> 1206 | F16: =$E16 -> 1206 | G16: =$E16 -> 1206 | H16: =$E16 -> 1206 | I16: =$E16 -> 1206 | J16: =$E16 -> 1206
A17: PP&E, Net | B17: =Historicals!B33 -> 9841 | C17: =Historicals!C33 -> 9236 | D17: =Historicals!D33 -> 10303 | E17: =Historicals!E33 -> 9613 | F17: ='PP&E'!F8 -> 10720.437 | G17: ='PP&E'!G8 -> 11877.709 | H17: ='PP&E'!H8 -> 13081.272 | I17: ='PP&E'!I8 -> 14326.959 | J17: ='PP&E'!J8 -> 15610.017
A18: Trademarks with Indefinite Lives | B18: =Historicals!B34 -> 14214 | C18: =Historicals!C34 -> 14349 | D18: =Historicals!D34 -> 13301 | E18: =Historicals!E34 -> 12531 | F18: =$E18 -> 12531 | G18: =$E18 -> 12531 | H18: =$E18 -> 12531 | I18: =$E18 -> 12531 | J18: =$E18 -> 12531
A19: Goodwill | B19: =Historicals!B35 -> 18782 | C19: =Historicals!C35 -> 18358 | D19: =Historicals!D35 -> 18139 | E19: =Historicals!E35 -> 15491 | F19: =$E19 -> 15491 | G19: =$E19 -> 15491 | H19: =$E19 -> 15491 | I19: =$E19 -> 15491 | J19: =$E19 -> 15491
A20: Other Noncurrent Assets | B20: =Historicals!B36 -> 7325 | C20: =Historicals!C36 -> 7796 | D20: =Historicals!D36 -> 13403 | E20: =Historicals!E36 -> 14696 | F20: =$E20 -> 14696 | G20: =$E20 -> 14696 | H20: =$E20 -> 14696 | I20: =$E20 -> 14696 | J20: =$E20 -> 14696
A21: Total Assets | B21: =Historicals!B37 -> 92763 | C21: =Historicals!C37 -> 97703 | D21: =Historicals!D37 -> 100549 | E21: =Historicals!E37 -> 104816 | F21: =F13+SUM(F15:F20) -> 109999.48 | G21: =G13+SUM(G15:G20) -> 115309.33 | H21: =H13+SUM(H15:H20) -> 120730.5 | I21: =I13+SUM(I15:I20) -> 126239.74 | J21: =J13+SUM(J15:J20) -> 131812.27
A23: LIABILITIES & EQUITY
A24: Accounts Payable & Accrued Expenses | B24: =Historicals!B38 -> 15749 | C24: =Historicals!C38 -> 15485 | D24: =Historicals!D38 -> 21712 | E24: =Historicals!E38 -> 14813 | F24: ='Working Capital'!F9 -> 15554.457 | G24: ='Working Capital'!G9 -> 16254.408 | H24: ='Working Capital'!H9 -> 16904.584 | I24: ='Working Capital'!I9 -> 17496.245 | J24: ='Working Capital'!J9 -> 18021.132
A25: Loans & Notes Payable | B25: =Historicals!B39 -> 2373 | C25: =Historicals!C39 -> 4557 | D25: =Historicals!D39 -> 1499 | E25: =Historicals!E39 -> 1551 | F25: =$E25 -> 1551 | G25: =$E25 -> 1551 | H25: =$E25 -> 1551 | I25: =$E25 -> 1551 | J25: =$E25 -> 1551
A26: Current Maturities of Long-Term Debt | B26: =Historicals!B40 -> 399 | C26: =Historicals!C40 -> 1960 | D26: =Historicals!D40 -> 648 | E26: =Historicals!E40 -> 1822 | F26: =$E26 -> 1822 | G26: =$E26 -> 1822 | H26: =$E26 -> 1822 | I26: =$E26 -> 1822 | J26: =$E26 -> 1822
A27: Accrued Income Taxes | B27: =Historicals!B41 -> 1203 | C27: =Historicals!C41 -> 1569 | D27: =Historicals!D41 -> 1387 | E27: =Historicals!E41 -> 525 | F27: =$E27 -> 525 | G27: =$E27 -> 525 | H27: =$E27 -> 525 | I27: =$E27 -> 525 | J27: =$E27 -> 525
A28: Liabilities Held for Sale | B28: =Historicals!B42 -> — | C28: =Historicals!C42 -> — | D28: =Historicals!D42 -> 3 | E28: =Historicals!E42 -> 2570 | F28: =$E28 -> 2570 | G28: =$E28 -> 2570 | H28: =$E28 -> 2570 | I28: =$E28 -> 2570 | J28: =$E28 -> 2570
A29: Total Current Liabilities | B29: =Historicals!B43 -> 19724 | C29: =Historicals!C43 -> 23571 | D29: =Historicals!D43 -> 25249 | E29: =Historicals!E43 -> 21281 | F29: =SUM(F24:F28) -> 22022.457 | G29: =SUM(G24:G28) -> 22722.408 | H29: =SUM(H24:H28) -> 23372.584 | I29: =SUM(I24:I28) -> 23964.245 | J29: =SUM(J24:J28) -> 24489.132
A30: Long-Term Debt | B30: =Historicals!B44 -> 36377 | C30: =Historicals!C44 -> 35547 | D30: =Historicals!D44 -> 42375 | E30: =Historicals!E44 -> 42119 | F30: =Debt!F8-$E25-$E26 -> 42119 | G30: =Debt!G8-$E25-$E26 -> 42119 | H30: =Debt!H8-$E25-$E26 -> 42119 | I30: =Debt!I8-$E25-$E26 -> 42119 | J30: =Debt!J8-$E25-$E26 -> 42119
A31: Other Noncurrent Liabilities | B31: =Historicals!B45 -> 7922 | C31: =Historicals!C45 -> 8466 | D31: =Historicals!D45 -> 4084 | E31: =Historicals!E45 -> 4735 | F31: =$E31 -> 4735 | G31: =$E31 -> 4735 | H31: =$E31 -> 4735 | I31: =$E31 -> 4735 | J31: =$E31 -> 4735
A32: Deferred Income Tax Liabilities | B32: =Historicals!B46 -> 2914 | C32: =Historicals!C46 -> 2639 | D32: =Historicals!D46 -> 2469 | E32: =Historicals!E46 -> 2406 | F32: =$E32 -> 2406 | G32: =$E32 -> 2406 | H32: =$E32 -> 2406 | I32: =$E32 -> 2406 | J32: =$E32 -> 2406
A33: Total Liabilities | B33: =B29+B30+B31+B32 -> 66937 | C33: =C29+C30+C31+C32 -> 70223 | D33: =D29+D30+D31+D32 -> 74177 | E33: =E29+E30+E31+E32 -> 70541 | F33: =F29+SUM(F30:F32) -> 71282.457 | G33: =G29+SUM(G30:G32) -> 71982.408 | H33: =H29+SUM(H30:H32) -> 72632.584 | I33: =I29+SUM(I30:I32) -> 73224.245 | J33: =J29+SUM(J30:J32) -> 73749.132
A34: Equity Attributable to Shareowners | B34: =Historicals!B47 -> 24105 | C34: =Historicals!C47 -> 25941 | D34: =Historicals!D47 -> 24856 | E34: =Historicals!E47 -> 32169 | F34: =E34+'Income Statement'!F20-('Income Statement'!F20*Assumptions!F12) -> 36611.021 | G34: =F34+'Income Statement'!G20-('Income Statement'!G20*Assumptions!G12) -> 41220.921 | H34: =G34+'Income Statement'!H20-('Income Statement'!H20*Assumptions!H12) -> 45991.913 | I34: =H34+'Income Statement'!I20-('Income Statement'!I20*Assumptions!I12) -> 50909.499 | J34: =I34+'Income Statement'!J20-('Income Statement'!J20*Assumptions!J12) -> 55957.135
A35: Equity Attributable to Noncontrolling Interests | B35: =Historicals!B48 -> 1721 | C35: =Historicals!C48 -> 1539 | D35: =Historicals!D48 -> 1516 | E35: =Historicals!E48 -> 2106 | F35: =$E35 -> 2106 | G35: =$E35 -> 2106 | H35: =$E35 -> 2106 | I35: =$E35 -> 2106 | J35: =$E35 -> 2106
A36: Total Equity | B36: =Historicals!B49 -> 25826 | C36: =Historicals!C49 -> 27480 | D36: =Historicals!D49 -> 26372 | E36: =Historicals!E49 -> 34275 | F36: =F34+F35 -> 38717.021 | G36: =G34+G35 -> 43326.921 | H36: =H34+H35 -> 48097.913 | I36: =I34+I35 -> 53015.499 | J36: =J34+J35 -> 58063.135
A37: Total Liabilities & Equity | B37: =Historicals!B50 -> 92763 | C37: =Historicals!C50 -> 97703 | D37: =Historicals!D50 -> 100549 | E37: =Historicals!E50 -> 104816 | F37: =F33+F36 -> 109999.48 | G37: =G33+G36 -> 115309.33 | H37: =H33+H36 -> 120730.5 | I37: =I33+I36 -> 126239.74 | J37: =J33+J36 -> 131812.27
A38: Balance Check | B38: =B21-B37 -> 0 | C38: =C21-C37 -> 0 | D38: =D21-D37 -> 0 | E38: =E21-E37 -> 0 | F38: =F21-F37 -> 0 | G38: =G21-G37 -> 0 | H38: =H21-H37 -> 0 | I38: =I21-I37 -> 0 | J38: =J21-J37 -> 0

Sheet Cash Flow
A1: CASH FLOW STATEMENT
A3: Fiscal Year | B3: 2022A | C3: 2023A | D3: 2024A | E3: 2025A | F3: 2026E | G3: 2027E | H3: 2028E | I3: 2029E | J3: 2030E
A5: OPERATING ACTIVITIES
A6: Net Income | B6: =Historicals!B56 -> 9571 | C6: =Historicals!C56 -> 10703 | D6: =Historicals!D56 -> 10649 | E6: =Historicals!E56 -> 13137 | F6: ='Income Statement'!F20 -> 13460.669 | G6: ='Income Statement'!G20 -> 13969.394 | H6: ='Income Statement'!H20 -> 14457.552 | I6: ='Income Statement'!I20 -> 14901.776 | J6: ='Income Statement'!J20 -> 15295.866
A7: D&A | B7: =Historicals!B57 -> 1260 | C7: =Historicals!C57 -> 1128 | D7: =Historicals!D57 -> 1075 | E7: =Historicals!E57 -> 1050 | F7: ='PP&E'!F7 -> 1107.4371 | G7: ='PP&E'!G7 -> 1157.2718 | H7: ='PP&E'!H7 -> 1203.5626 | I7: ='PP&E'!I7 -> 1245.6873 | J7: ='PP&E'!J7 -> 1283.058
A8: Change in Working Capital | B8: — | C8: =-'Working Capital'!C12 -> -378 | D8: =-'Working Capital'!D12 -> 5764 | E8: =-'Working Capital'!E12 -> -6065 | F8: =-'Working Capital'!F12 -> 366.82306 | G8: =-'Working Capital'!G12 -> 347.25704 | H8: =-'Working Capital'!H12 -> 322.5632 | I8: =-'Working Capital'!I12 -> 293.53252 | J8: =-'Working Capital'!J12 -> 260.40527
A9: Cash Flow from Operations | B9: =Historicals!B66 -> 11018 | C9: =Historicals!C66 -> 11599 | D9: =Historicals!D66 -> 6805 | E9: =Historicals!E66 -> 7408 | F9: =SUM(F6:F8) -> 14934.929 | G9: =SUM(G6:G8) -> 15473.922 | H9: =SUM(H6:H8) -> 15983.678 | I9: =SUM(I6:I8) -> 16440.996 | J9: =SUM(J6:J8) -> 16839.329
A11: INVESTING ACTIVITIES
A12: CapEx | B12: =Historicals!B72 -> -1484 | C12: =Historicals!C72 -> -1852 | D12: =Historicals!D72 -> -2064 | E12: =Historicals!E72 -> -2112 | F12: =-'PP&E'!F6 -> -2214.8742 | G12: =-'PP&E'!G6 -> -2314.5435 | H12: =-'PP&E'!H6 -> -2407.1253 | I12: =-'PP&E'!I6 -> -2491.3747 | J12: =-'PP&E'!J6 -> -2566.1159
A13: Cash Flow from Investing | B13: =Historicals!B76 -> -763 | C13: =Historicals!C76 -> -3349 | D13: =Historicals!D76 -> 2524 | E13: =Historicals!E76 -> -67 | F13: =F12 -> -2214.8742 | G13: =G12 -> -2314.5435 | H13: =H12 -> -2407.1253 | I13: =I12 -> -2491.3747 | J13: =J12 -> -2566.1159
A15: FINANCING ACTIVITIES
A16: Debt Issuance | B16: =Historicals!B78 -> 3972 | C16: =Historicals!C78 -> 6891 | D16: =Historicals!D78 -> 12061 | E16: =Historicals!E78 -> 4980 | F16: =Debt!F6 -> 0 | G16: =Debt!G6 -> 0 | H16: =Debt!H6 -> 0 | I16: =Debt!I6 -> 0 | J16: =Debt!J6 -> 0
A17: Debt Repayment | B17: =Historicals!B79 -> -4930 | C17: =Historicals!C79 -> -5034 | D17: =Historicals!D79 -> -9533 | E17: =Historicals!E79 -> -4967 | F17: =Debt!F7 -> 0 | G17: =Debt!G7 -> 0 | H17: =Debt!H7 -> 0 | I17: =Debt!I7 -> 0 | J17: =Debt!J7 -> 0
A18: Dividends | B18: =Historicals!B82 -> -7616 | C18: =Historicals!C82 -> -7952 | D18: =Historicals!D82 -> -8359 | E18: =Historicals!E82 -> -8779 | F18: =-'Income Statement'!F20*Assumptions!F12 -> -9018.6484 | G18: =-'Income Statement'!G20*Assumptions!G12 -> -9359.4937 | H18: =-'Income Statement'!H20*Assumptions!H12 -> -9686.5598 | I18: =-'Income Statement'!I20*Assumptions!I12 -> -9984.1899 | J18: =-'Income Statement'!J20*Assumptions!J12 -> -10248.23
A19: Cash Flow from Financing | B19: =Historicals!B85 -> -10250 | C19: =Historicals!C85 -> -8310 | D19: =Historicals!D85 -> -6910 | E19: =Historicals!E85 -> -8140 | F19: =SUM(F16:F18) -> -9018.6484 | G19: =SUM(G16:G18) -> -9359.4937 | H19: =SUM(H16:H18) -> -9686.5598 | I19: =SUM(I16:I18) -> -9984.1899 | J19: =SUM(J16:J18) -> -10248.23
A21: Net Change in Cash | B21: =Historicals!B88 -> -200 | C21: =Historicals!C88 -> -133 | D21: =Historicals!D88 -> 1796 | E21: =Historicals!E88 -> -478 | F21: =F9+F13+F19 -> 3701.4068 | G21: =G9+G13+G19 -> 3799.8852 | H21: =H9+H13+H19 -> 3889.9927 | I21: =I9+I13+I19 -> 3965.4312 | J21: =J9+J13+J19 -> 4024.9831
A22: Beginning Cash | B22: =Historicals!B89 -> 10025 | C22: =Historicals!C89 -> 9825 | D22: =Historicals!D89 -> 9692 | E22: =Historicals!E89 -> 11488 | F22: =E23 -> 10270 | G22: =F23 -> 13971.407 | H22: =G23 -> 17771.292 | I22: =H23 -> 21661.285 | J22: =I23 -> 25626.716
A23: Ending Cash | B23: =Historicals!B90 -> 9825 | C23: =Historicals!C90 -> 9692 | D23: =Historicals!D90 -> 11488 | E23: =Historicals!E92 -> 10270 | F23: =F22+F21 -> 13971.407 | G23: =G22+G21 -> 17771.292 | H23: =H22+H21 -> 21661.285 | I23: =I22+I21 -> 25626.716 | J23: =J22+J21 -> 29651.699

Sheet Working Capital
A1: WORKING CAPITAL
B3: 2022A | C3: 2023A | D3: 2024A | E3: 2025A | F3: 2026E | G3: 2027E | H3: 2028E | I3: 2029E | J3: 2030E
A5: Accounts Receivable | B5: ='Balance Sheet'!B9 -> 3487 | C5: ='Balance Sheet'!C9 -> 3410 | D5: ='Balance Sheet'!D9 -> 3569 | E5: ='Balance Sheet'!E9 -> 3038 | F5: =F6*'Income Statement'!F4 -> 3191.4324 | G5: =G6*'Income Statement'!G4 -> 3335.0468 | H5: =H6*'Income Statement'!H4 -> 3468.4487 | I5: =I6*'Income Statement'!I4 -> 3589.8444 | J5: =J6*'Income Statement'!J4 -> 3697.5397
A6: AR % of Revenue | B6: =B5/'Income Statement'!B4 -> 0.08108548 | C6: =C5/'Income Statement'!C4 -> 0.074529003 | D6: =D5/'Income Statement'!D4 -> 0.075837742 | E6: =E5/'Income Statement'!E4 -> 0.063369558 | F6: 0.0634 | G6: 0.0634 | H6: 0.0634 | I6: 0.0634 | J6: 0.0634
A7: Inventory | B7: ='Balance Sheet'!B10 -> 4233 | C7: ='Balance Sheet'!C10 -> 4424 | D7: ='Balance Sheet'!D10 -> 4728 | E7: ='Balance Sheet'!E10 -> 4425 | F7: =F8*'Income Statement'!F4 -> 4646.202 | G7: =G8*'Income Statement'!G4 -> 4855.2811 | H7: =H8*'Income Statement'!H4 -> 5049.4924 | I7: =I8*'Income Statement'!I4 -> 5226.2246 | J7: =J8*'Income Statement'!J4 -> 5383.0113
A8: Inventory % of Revenue | B8: =B7/'Income Statement'!B4 -> 0.098432704 | C8: =C7/'Income Statement'!C4 -> 0.096691 | D8: =D7/'Income Statement'!D4 -> 0.10046535 | E8: =E7/'Income Statement'!E4 -> 0.092300953 | F8: 0.0923 | G8: 0.0923 | H8: 0.0923 | I8: 0.0923 | J8: 0.0923
A9: Accounts Payable | B9: ='Balance Sheet'!B24 -> 15749 | C9: ='Balance Sheet'!C24 -> 15485 | D9: ='Balance Sheet'!D24 -> 21712 | E9: ='Balance Sheet'!E24 -> 14813 | F9: =F10*'Income Statement'!F4 -> 15554.457 | G9: =G10*'Income Statement'!G4 -> 16254.408 | H9: =H10*'Income Statement'!H4 -> 16904.584 | I9: =I10*'Income Statement'!I4 -> 17496.245 | J9: =J10*'Income Statement'!J4 -> 18021.132
A10: AP % of Revenue | B10: =B9/'Income Statement'!B4 -> 0.36622175 | C10: =C9/'Income Statement'!C4 -> 0.33844035 | D10: =D9/'Income Statement'!D4 -> 0.46135866 | E10: =E9/'Income Statement'!E4 -> 0.30898396 | F10: 0.309 | G10: 0.309 | H10: 0.309 | I10: 0.309 | J10: 0.309
A11: Operating Working Capital | B11: =B5+B7-B9 -> -8029 | C11: =C5+C7-C9 -> -7651 | D11: =D5+D7-D9 -> -13415 | E11: =E5+E7-E9 -> -7350 | F11: =F5+F7-F9 -> -7716.8231 | G11: =G5+G7-G9 -> -8064.0801 | H11: =H5+H7-H9 -> -8386.6433 | I11: =I5+I7-I9 -> -8680.1758 | J11: =J5+J7-J9 -> -8940.5811
A12: Change in Working Capital | B12: — | C12: =C11-B11 -> 378 | D12: =D11-C11 -> -5764 | E12: =E11-D11 -> 6065 | F12: =F11-E11 -> -366.82306 | G12: =G11-F11 -> -347.25704 | H12: =H11-G11 -> -322.5632 | I12: =I11-H11 -> -293.53252 | J12: =J11-I11 -> -260.40527

Sheet PP&E
A1: PP&E SCHEDULE
A3: Fiscal Year | B3: 2022A | C3: 2023A | D3: 2024A | E3: 2025A | F3: 2026E | G3: 2027E | H3: 2028E | I3: 2029E | J3: 2030E
A5: Beginning PP&E | B5: — | C5: =B8 -> 9841 | D5: =C8 -> 9236 | E5: =D8 -> 10303 | F5: =E8 -> 9613 | G5: =F8 -> 10720.437 | H5: =G8 -> 11877.709 | I5: =H8 -> 13081.272 | J5: =I8 -> 14326.959
A6: CapEx | B6: =-Historicals!B72 -> 1484 | C6: =-Historicals!C72 -> 1852 | D6: =-Historicals!D72 -> 2064 | E6: =-Historicals!E72 -> 2112 | F6: ='Income Statement'!F4*Assumptions!F11 -> 2214.8742 | G6: ='Income Statement'!G4*Assumptions!G11 -> 2314.5435 | H6: ='Income Statement'!H4*Assumptions!H11 -> 2407.1253 | I6: ='Income Statement'!I4*Assumptions!I11 -> 2491.3747 | J6: ='Income Statement'!J4*Assumptions!J11 -> 2566.1159
A7: D&A | B7: =Historicals!B57 -> 1260 | C7: =Historicals!C57 -> 1128 | D7: =Historicals!D57 -> 1075 | E7: =Historicals!E57 -> 1050 | F7: ='Income Statement'!F4*Assumptions!F10 -> 1107.4371 | G7: ='Income Statement'!G4*Assumptions!G10 -> 1157.2718 | H7: ='Income Statement'!H4*Assumptions!H10 -> 1203.5626 | I7: ='Income Statement'!I4*Assumptions!I10 -> 1245.6873 | J7: ='Income Statement'!J4*Assumptions!J10 -> 1283.058
A8: Ending PP&E | B8: ='Balance Sheet'!B17 -> 9841 | C8: ='Balance Sheet'!C17 -> 9236 | D8: ='Balance Sheet'!D17 -> 10303 | E8: ='Balance Sheet'!E17 -> 9613 | F8: =F5+F6-F7 -> 10720.437 | G8: =G5+G6-G7 -> 11877.709 | H8: =H5+H6-H7 -> 13081.272 | I8: =I5+I6-I7 -> 14326.959 | J8: =J5+J6-J7 -> 15610.017

Sheet Debt
A1: DEBT SCHEDULE
A3: Fiscal Year | B3: 2022A | C3: 2023A | D3: 2024A | E3: 2025A | F3: 2026E | G3: 2027E | H3: 2028E | I3: 2029E | J3: 2030E
A5: Beginning Debt | B5: — | C5: =B8 -> 39149 | D5: =C8 -> 42064 | E5: =D8 -> 44522 | F5: =E8 -> 45492 | G5: =F8 -> 45492 | H5: =G8 -> 45492 | I5: =H8 -> 45492 | J5: =I8 -> 45492
A6: Debt Issuance | B6: =Historicals!B78 -> 3972 | C6: =Historicals!C78 -> 6891 | D6: =Historicals!D78 -> 12061 | E6: =Historicals!E78 -> 4980 | F6: =0 -> 0 | G6: =0 -> 0 | H6: =0 -> 0 | I6: =0 -> 0 | J6: =0 -> 0
A7: Debt Repayment | B7: =Historicals!B79 -> -4930 | C7: =Historicals!C79 -> -5034 | D7: =Historicals!D79 -> -9533 | E7: =Historicals!E79 -> -4967 | F7: =0 -> 0 | G7: =0 -> 0 | H7: =0 -> 0 | I7: =0 -> 0 | J7: =0 -> 0
A8: Ending Debt | B8: ='Balance Sheet'!B25+'Balance Sheet'!B26+'Balance Sheet'!B30 -> 39149 | C8: ='Balance Sheet'!C25+'Balance Sheet'!C26+'Balance Sheet'!C30 -> 42064 | D8: ='Balance Sheet'!D25+'Balance Sheet'!D26+'Balance Sheet'!D30 -> 44522 | E8: ='Balance Sheet'!E25+'Balance Sheet'!E26+'Balance Sheet'!E30 -> 45492 | F8: =F5+F6+F7 -> 45492 | G8: =G5+G6+G7 -> 45492 | H8: =H5+H6+H7 -> 45492 | I8: =I5+I6+I7 -> 45492 | J8: =J5+J6+J7 -> 45492
A9: Average Debt | B9: — | C9: =(C5+C8)/2 -> 40606.5 | D9: =(D5+D8)/2 -> 43293 | E9: =(E5+E8)/2 -> 45007 | F9: =(F5+F8)/2 -> 45492 | G9: =(G5+G8)/2 -> 45492 | H9: =(H5+H8)/2 -> 45492 | I9: =(I5+I8)/2 -> 45492 | J9: =(J5+J8)/2 -> 45492
A10: Interest Rate | B10: — | C10: ='Income Statement'!C14/C9 -> 0.037604817 | D10: ='Income Statement'!D14/D9 -> 0.038250987 | E10: ='Income Statement'!E14/E9 -> 0.036749839 | F10: =3.7% -> 0.037 | G10: =3.7% -> 0.037 | H10: =3.7% -> 0.037 | I10: =3.7% -> 0.037 | J10: =3.7% -> 0.037
A11: Interest Expense | F11: =F9*F10 -> 1683.204 | G11: =G9*G10 -> 1683.204 | H11: =H9*H10 -> 1683.204 | I11: =I9*I10 -> 1683.204 | J11: =J9*J10 -> 1683.204

Sheet DCF
A1: DCF VALUATION
A3: Fiscal Year | B3: 2026E | C3: 2027E | D3: 2028E | E3: 2029E | F3: 2030E
A5: EBIT | B5: ='Income Statement'!F11 -> 14598.034 | C5: ='Income Statement'!G11 -> 15254.946 | D5: ='Income Statement'!H11 -> 15865.144 | E5: ='Income Statement'!I11 -> 16420.424 | F5: ='Income Statement'!J11 -> 16913.037
A6: Tax Rate | B6: ='Income Statement'!F19 -> 0.199 | C6: ='Income Statement'!G19 -> 0.2 | D6: ='Income Statement'!H19 -> 0.2 | E6: ='Income Statement'!I19 -> 0.2 | F6: ='Income Statement'!J19 -> 0.2
A7: NOPAT | B7: =B5*(1-B6) -> 11693.026 | C7: =C5*(1-C6) -> 12203.957 | D7: =D5*(1-D6) -> 12692.115 | E7: =E5*(1-E6) -> 13136.339 | F7: =F5*(1-F6) -> 13530.429
A8: D&A | B8: ='PP&E'!F7 -> 1107.4371 | C8: ='PP&E'!G7 -> 1157.2718 | D8: ='PP&E'!H7 -> 1203.5626 | E8: ='PP&E'!I7 -> 1245.6873 | F8: ='PP&E'!J7 -> 1283.058
A9: CapEx | B9: =-'PP&E'!F6 -> -2214.8742 | C9: =-'PP&E'!G6 -> -2314.5435 | D9: =-'PP&E'!H6 -> -2407.1253 | E9: =-'PP&E'!I6 -> -2491.3747 | F9: =-'PP&E'!J6 -> -2566.1159
A10: Change in Working Capital | B10: ='Working Capital'!F12 -> -366.82306 | C10: ='Working Capital'!G12 -> -347.25704 | D10: ='Working Capital'!H12 -> -322.5632 | E10: ='Working Capital'!I12 -> -293.53252 | F10: ='Working Capital'!J12 -> -260.40527
A11: FCFF | B11: =B7+B8+B9-B10 -> 10952.412 | C11: =C7+C8+C9-C10 -> 11393.942 | D11: =D7+D8+D9-D10 -> 11811.116 | E11: =E7+E8+E9-E10 -> 12184.184 | F11: =F7+F8+F9-F10 -> 12507.777
A13: Discount Period | B13: =1 -> 1 | C13: =B13+1 -> 2 | D13: =C13+1 -> 3 | E13: =D13+1 -> 4 | F13: =E13+1 -> 5
A14: Discount Factor | B14: =1/(1+$B$28)^B13 -> 0.93457944 | C14: =1/(1+$B$28)^C13 -> 0.87343873 | D14: =1/(1+$B$28)^D13 -> 0.81629788 | E14: =1/(1+$B$28)^E13 -> 0.76289521 | F14: =1/(1+$B$28)^F13 -> 0.71298618
A15: PV of FCFF | B15: =B11*B14 -> 10235.899 | C15: =C11*C14 -> 9951.9103 | D15: =D11*D14 -> 9641.3887 | E15: =E11*E14 -> 9295.2559 | F15: =F11*F14 -> 8917.8719
A17: Terminal Growth Rate | B17: 0.025
A18: Terminal Value | B18: =F11*(1+$B$17)/($B$28-$B$17) -> 284899.36
A19: PV of Terminal Value | B19: =B18*F14 -> 203129.3
A21: Enterprise Value | B21: =SUM(B15:F15)+B19 -> 251171.63
A22: Less: Debt | B22: =Debt!F8 -> 45492
A23: Add: Cash | B23: ='Balance Sheet'!E6 -> 10270
A24: Equity Value | B24: =B21-B22+B23 -> 215949.63
A25: Shares Outstanding | B25: 4313
A26: Implied Share Price | B26: =B24/B25 -> 50.069471
A28: WACC | B28: 0.07

Sheet Sensitivity
A1: WACC | B1: 0.02 | C1: 0.0225 | D1: 0.025 | E1: 0.0275 | F1: 0.03
A2: 0.06 | B2: {=(SUMPRODUCT(DCF!$B$11:$F$11,1/(1+$A2)^{1,2,3,4,5})+((DCF!$F$11*(1+B$1))/($A2-B$1))/(1+$A2)^5-DCF!$B$22+DCF!$B$23)/DCF!$B$25} -> 58.544436 | C2: {=(SUMPRODUCT(DCF!$B$11:$F$11,1/(1+$A2)^{1,2,3,4,5})+((DCF!$F$11*(1+C$1))/($A2-C$1))/(1+$A2)^5-DCF!$B$22+DCF!$B$23)/DCF!$B$25} -> 62.372912 | D2: {=(SUMPRODUCT(DCF!$B$11:$F$11,1/(1+$A2)^{1,2,3,4,5})+((DCF!$F$11*(1+D$1))/($A2-D$1))/(1+$A2)^5-DCF!$B$22+DCF!$B$23)/DCF!$B$25} -> 66.748314 | E2: {=(SUMPRODUCT(DCF!$B$11:$F$11,1/(1+$A2)^{1,2,3,4,5})+((DCF!$F$11*(1+E$1))/($A2-E$1))/(1+$A2)^5-DCF!$B$22+DCF!$B$23)/DCF!$B$25} -> 71.796854 | F2: {=(SUMPRODUCT(DCF!$B$11:$F$11,1/(1+$A2)^{1,2,3,4,5})+((DCF!$F$11*(1+F$1))/($A2-F$1))/(1+$A2)^5-DCF!$B$22+DCF!$B$23)/DCF!$B$25} -> 77.686817
A3: 0.065 | B3: {=(SUMPRODUCT(DCF!$B$11:$F$11,1/(1+$A3)^{1,2,3,4,5})+((DCF!$F$11*(1+B$1))/($A3-B$1))/(1+$A3)^5-DCF!$B$22+DCF!$B$23)/DCF!$B$25} -> 51.104524 | C3: {=(SUMPRODUCT(DCF!$B$11:$F$11,1/(1+$A3)^{1,2,3,4,5})+((DCF!$F$11*(1+C$1))/($A3-C$1))/(1+$A3)^5-DCF!$B$22+DCF!$B$23)/DCF!$B$25} -> 54.051257 | D3: {=(SUMPRODUCT(DCF!$B$11:$F$11,1/(1+$A3)^{1,2,3,4,5})+((DCF!$F$11*(1+D$1))/($A3-D$1))/(1+$A3)^5-DCF!$B$22+DCF!$B$23)/DCF!$B$25} -> 57.366332 | E3: {=(SUMPRODUCT(DCF!$B$11:$F$11,1/(1+$A3)^{1,2,3,4,5})+((DCF!$F$11*(1+E$1))/($A3-E$1))/(1+$A3)^5-DCF!$B$22+DCF!$B$23)/DCF!$B$25} -> 61.123416 | F3: {=(SUMPRODUCT(DCF!$B$11:$F$11,1/(1+$A3)^{1,2,3,4,5})+((DCF!$F$11*(1+F$1))/($A3-F$1))/(1+$A3)^5-DCF!$B$22+DCF!$B$23)/DCF!$B$25} -> 65.417227
A4: 0.07 | B4: {=(SUMPRODUCT(DCF!$B$11:$F$11,1/(1+$A4)^{1,2,3,4,5})+((DCF!$F$11*(1+B$1))/($A4-B$1))/(1+$A4)^5-DCF!$B$22+DCF!$B$23)/DCF!$B$25} -> 45.153005 | C4: {=(SUMPRODUCT(DCF!$B$11:$F$11,1/(1+$A4)^{1,2,3,4,5})+((DCF!$F$11*(1+C$1))/($A4-C$1))/(1+$A4)^5-DCF!$B$22+DCF!$B$23)/DCF!$B$25} -> 47.481858 | D4: {=(SUMPRODUCT(DCF!$B$11:$F$11,1/(1+$A4)^{1,2,3,4,5})+((DCF!$F$11*(1+D$1))/($A4-D$1))/(1+$A4)^5-DCF!$B$22+DCF!$B$23)/DCF!$B$25} -> 50.069471 | E4: {=(SUMPRODUCT(DCF!$B$11:$F$11,1/(1+$A4)^{1,2,3,4,5})+((DCF!$F$11*(1+E$1))/($A4-E$1))/(1+$A4)^5-DCF!$B$22+DCF!$B$23)/DCF!$B$25} -> 52.96151 | F4: {=(SUMPRODUCT(DCF!$B$11:$F$11,1/(1+$A4)^{1,2,3,4,5})+((DCF!$F$11*(1+F$1))/($A4-F$1))/(1+$A4)^5-DCF!$B$22+DCF!$B$23)/DCF!$B$25} -> 56.215054
A5: 0.075 | B5: {=(SUMPRODUCT(DCF!$B$11:$F$11,1/(1+$A5)^{1,2,3,4,5})+((DCF!$F$11*(1+B$1))/($A5-B$1))/(1+$A5)^5-DCF!$B$22+DCF!$B$23)/DCF!$B$25} -> 40.283946 | C5: {=(SUMPRODUCT(DCF!$B$11:$F$11,1/(1+$A5)^{1,2,3,4,5})+((DCF!$F$11*(1+C$1))/($A5-C$1))/(1+$A5)^5-DCF!$B$22+DCF!$B$23)/DCF!$B$25} -> 42.164063 | D5: {=(SUMPRODUCT(DCF!$B$11:$F$11,1/(1+$A5)^{1,2,3,4,5})+((DCF!$F$11*(1+D$1))/($A5-D$1))/(1+$A5)^5-DCF!$B$22+DCF!$B$23)/DCF!$B$25} -> 44.232191 | E5: {=(SUMPRODUCT(DCF!$B$11:$F$11,1/(1+$A5)^{1,2,3,4,5})+((DCF!$F$11*(1+E$1))/($A5-E$1))/(1+$A5)^5-DCF!$B$22+DCF!$B$23)/DCF!$B$25} -> 46.518017 | F5: {=(SUMPRODUCT(DCF!$B$11:$F$11,1/(1+$A5)^{1,2,3,4,5})+((DCF!$F$11*(1+F$1))/($A5-F$1))/(1+$A5)^5-DCF!$B$22+DCF!$B$23)/DCF!$B$25} -> 49.057824
A6: 0.08 | B6: {=(SUMPRODUCT(DCF!$B$11:$F$11,1/(1+$A6)^{1,2,3,4,5})+((DCF!$F$11*(1+B$1))/($A6-B$1))/(1+$A6)^5-DCF!$B$22+DCF!$B$23)/DCF!$B$25} -> 36.226724 | C6: {=(SUMPRODUCT(DCF!$B$11:$F$11,1/(1+$A6)^{1,2,3,4,5})+((DCF!$F$11*(1+C$1))/($A6-C$1))/(1+$A6)^5-DCF!$B$22+DCF!$B$23)/DCF!$B$25} -> 37.771362 | D6: {=(SUMPRODUCT(DCF!$B$11:$F$11,1/(1+$A6)^{1,2,3,4,5})+((DCF!$F$11*(1+D$1))/($A6-D$1))/(1+$A6)^5-DCF!$B$22+DCF!$B$23)/DCF!$B$25} -> 39.456421 | E6: {=(SUMPRODUCT(DCF!$B$11:$F$11,1/(1+$A6)^{1,2,3,4,5})+((DCF!$F$11*(1+E$1))/($A6-E$1))/(1+$A6)^5-DCF!$B$22+DCF!$B$23)/DCF!$B$25} -> 41.301961 | F6: {=(SUMPRODUCT(DCF!$B$11:$F$11,1/(1+$A6)^{1,2,3,4,5})+((DCF!$F$11*(1+F$1))/($A6-F$1))/(1+$A6)^5-DCF!$B$22+DCF!$B$23)/DCF!$B$25} -> 43.332056

Sheet Dashboard
A1: COCA-COLA FINANCIAL MODEL DASHBOARD
A2: The Coca-Cola Company (NYSE: KO)
A4: VALUATION SUMMARY | D4: OPERATING SUMMARY
A5: Enterprise Value | B5: =DCF!B21 -> 251171.63 | D5: Revenue 2025A | E5: ='Income Statement'!E4 -> 47941
A6: Less: Debt | B6: =DCF!B22 -> 45492 | D6: Revenue 2030E | E6: ='Income Statement'!J4 -> 58320.816
A7: Add: Cash | B7: =DCF!B23 -> 10270 | D7: Revenue CAGR | E7: =(E6/E5)^(1/5)-1 -> 0.039975961
A8: Equity Value | B8: =DCF!B24 -> 215949.63 | D8: EBIT 2025A | E8: ='Income Statement'!E11 -> 13762
A9: Shares Outstanding | B9: =DCF!B25 -> 4313 | D9: EBIT 2030E | E9: ='Income Statement'!J11 -> 16913.037
A10: Implied Share Price | B10: =DCF!B26 -> 50.069471 | D10: EBIT Margin 2030E | E10: ='Income Statement'!J12 -> 0.29
A11: WACC | B11: =DCF!B28 -> 0.07 | D11: Net Income 2025A | E11: ='Income Statement'!E20 -> 13137
A12: Terminal Growth Rate | B12: =DCF!B17 -> 0.025 | D12: Net Income 2030E | E12: ='Income Statement'!J20 -> 15295.866
A15: FORECAST SUMMARY | H15: VALUATION RANGE
A16: Metric | B16: 2026E | C16: 2027E | D16: 2028E | E16: 2029E | F16: 2030E | H16: Base Case | I16: =DCF!B26 -> 50.069471
A17: Revenue | B17: ='Income Statement'!F4 -> 50338.05 | C17: ='Income Statement'!G4 -> 52603.262 | D17: ='Income Statement'!H4 -> 54707.393 | E17: ='Income Statement'!I4 -> 56622.151 | F17: ='Income Statement'!J4 -> 58320.816 | H17: Downside Case | I17: =Sensitivity!B6 -> 36.226724
A18: EBIT | B18: ='Income Statement'!F11 -> 14598.034 | C18: ='Income Statement'!G11 -> 15254.946 | D18: ='Income Statement'!H11 -> 15865.144 | E18: ='Income Statement'!I11 -> 16420.424 | F18: ='Income Statement'!J11 -> 16913.037 | H18: Upside Case | I18: =Sensitivity!F2 -> 77.686817
A19: EBIT Margin | B19: ='Income Statement'!F12 -> 0.29 | C19: ='Income Statement'!G12 -> 0.29 | D19: ='Income Statement'!H12 -> 0.29 | E19: ='Income Statement'!I12 -> 0.29 | F19: ='Income Statement'!J12 -> 0.29
A20: Net Income | B20: ='Income Statement'!F20 -> 13460.669 | C20: ='Income Statement'!G20 -> 13969.394 | D20: ='Income Statement'!H20 -> 14457.552 | E20: ='Income Statement'!I20 -> 14901.776 | F20: ='Income Statement'!J20 -> 15295.866
A21: FCFF | B21: =DCF!B11 -> 10952.412 | C21: =DCF!C11 -> 11393.942 | D21: =DCF!D11 -> 11811.116 | E21: =DCF!E11 -> 12184.184 | F21: =DCF!F11 -> 12507.777
